Workbook

Sheet Dashboard
A1: STOCK PORTFOLIO TRACKER - FIFO METHOD
A3: Total Invested Value | B3: Current Portfolio Value | C3: Total Realized Profit | D3: Total Unrealized Profit | E3: Overall P&L | F3: Return %
A4: =SUMIFS(Holdings!D:D,Holdings!B:B,">0") | B4: =SUM(Holdings!F:F) | C4: =SUMIFS(Transactions!G:G,Transactions!C:C,"Sell")-SUMIF(FIFO_Buy_Table!H:H,">0",FIFO_Buy_Table!H:H)*SUMIF(FIFO_Buy_Table!H:H,">0",FIFO_Buy_Table!D:D) | D4: =SUM(Holdings!G:G) | E4: =C4+D4 | F4: =IF(A4=0,"",E4/A4)
A7: CURRENT HOLDINGS SUMMARY
A9: =Holdings!A1 | B9: =Holdings!B1 | C9: =Holdings!C1 | D9: =Holdings!D1 | E9: =Holdings!E1 | F9: =Holdings!F1
A10: =IFERROR(Holdings!A2,"") | B10: =IFERROR(Holdings!B2,"") | C10: =IFERROR(Holdings!C2,"") | D10: =IFERROR(Holdings!D2,"") | E10: =IFERROR(Holdings!E2,"") | F10: =IFERROR(Holdings!F2,"")
A11: =IFERROR(Holdings!A3,"") | B11: =IFERROR(Holdings!B3,"") | C11: =IFERROR(Holdings!C3,"") | D11: =IFERROR(Holdings!D3,"") | E11: =IFERROR(Holdings!E3,"") | F11: =IFERROR(Holdings!F3,"")
A12: =IFERROR(Holdings!A4,"") | B12: =IFERROR(Holdings!B4,"") | C12: =IFERROR(Holdings!C4,"") | D12: =IFERROR(Holdings!D4,"") | E12: =IFERROR(Holdings!E4,"") | F12: =IFERROR(Holdings!F4,"")
A13: =IFERROR(Holdings!A5,"") | B13: =IFERROR(Holdings!B5,"") | C13: =IFERROR(Holdings!C5,"") | D13: =IFERROR(Holdings!D5,"") | E13: =IFERROR(Holdings!E5,"") | F13: =IFERROR(Holdings!F5,"")
A14: =IFERROR(Holdings!A6,"") | B14: =IFERROR(Holdings!B6,"") | C14: =IFERROR(Holdings!C6,"") | D14: =IFERROR(Holdings!D6,"") | E14: =IFERROR(Holdings!E6,"") | F14: =IFERROR(Holdings!F6,"")
A15: =IFERROR(Holdings!A7,"") | B15: =IFERROR(Holdings!B7,"") | C15: =IFERROR(Holdings!C7,"") | D15: =IFERROR(Holdings!D7,"") | E15: =IFERROR(Holdings!E7,"") | F15: =IFERROR(Holdings!F7,"")
A16: =IFERROR(Holdings!A8,"") | B16: =IFERROR(Holdings!B8,"") | C16: =IFERROR(Holdings!C8,"") | D16: =IFERROR(Holdings!D8,"") | E16: =IFERROR(Holdings!E8,"") | F16: =IFERROR(Holdings!F8,"")
A17: =IFERROR(Holdings!A9,"") | B17: =IFERROR(Holdings!B9,"") | C17: =IFERROR(Holdings!C9,"") | D17: =IFERROR(Holdings!D9,"") | E17: =IFERROR(Holdings!E9,"") | F17: =IFERROR(Holdings!F9,"")
A18: =IFERROR(Holdings!A10,"") | B18: =IFERROR(Holdings!B10,"") | C18: =IFERROR(Holdings!C10,"") | D18: =IFERROR(Holdings!D10,"") | E18: =IFERROR(Holdings!E10,"") | F18: =IFERROR(Holdings!F10,"")
A19: =IFERROR(Holdings!A11,"") | B19: =IFERROR(Holdings!B11,"") | C19: =IFERROR(Holdings!C11,"") | D19: =IFERROR(Holdings!D11,"") | E19: =IFERROR(Holdings!E11,"") | F19: =IFERROR(Holdings!F11,"")
A20: =IFERROR(Holdings!A12,"") | B20: =IFERROR(Holdings!B12,"") | C20: =IFERROR(Holdings!C12,"") | D20: =IFERROR(Holdings!D12,"") | E20: =IFERROR(Holdings!E12,"") | F20: =IFERROR(Holdings!F12,"")
A21: =IFERROR(Holdings!A13,"") | B21: =IFERROR(Holdings!B13,"") | C21: =IFERROR(Holdings!C13,"") | D21: =IFERROR(Holdings!D13,"") | E21: =IFERROR(Holdings!E13,"") | F21: =IFERROR(Holdings!F13,"")
... A29: =IFERROR(Holdings!A21,"") | B29: =IFERROR(Holdings!B21,"") | C29: =IFERROR(Holdings!C21,"") | D29: =IFERROR(Holdings!D21,"") | E29: =IFERROR(Holdings!E21,"") | F29: =IFERROR(Holdings!F21,"")

Sheet Transactions
A1: Date | B1: Stock Name | C1: Transaction Type | D1: Quantity | E1: Price per Share | F1: Brokerage/STT | G1: Total Amount
G2: =IF(AND(D2<>"",E2<>""),D2*E2+IF(ISBLANK(F2),0,F2),"")
G3: =IF(AND(D3<>"",E3<>""),D3*E3+IF(ISBLANK(F3),0,F3),"")
G4: =IF(AND(D4<>"",E4<>""),D4*E4+IF(ISBLANK(F4),0,F4),"")
G5: =IF(AND(D5<>"",E5<>""),D5*E5+IF(ISBLANK(F5),0,F5),"")
G6: =IF(AND(D6<>"",E6<>""),D6*E6+IF(ISBLANK(F6),0,F6),"")
G7: =IF(AND(D7<>"",E7<>""),D7*E7+IF(ISBLANK(F7),0,F7),"")
G8: =IF(AND(D8<>"",E8<>""),D8*E8+IF(ISBLANK(F8),0,F8),"")
G9: =IF(AND(D9<>"",E9<>""),D9*E9+IF(ISBLANK(F9),0,F9),"")
G10: =IF(AND(D10<>"",E10<>""),D10*E10+IF(ISBLANK(F10),0,F10),"")
G11: =IF(AND(D11<>"",E11<>""),D11*E11+IF(ISBLANK(F11),0,F11),"")
G12: =IF(AND(D12<>"",E12<>""),D12*E12+IF(ISBLANK(F12),0,F12),"")
G13: =IF(AND(D13<>"",E13<>""),D13*E13+IF(ISBLANK(F13),0,F13),"")
... G1000: =IF(AND(D1000<>"",E1000<>""),D1000*E1000+IF(ISBLANK(F1000),0,F1000),"")

Sheet FIFO_Buy_Table
A1: Stock Name | B1: Buy Date | C1: Buy Qty | D1: Buy Price | E1: Total Value | F1: Cumulative Buy Qty | G1: Total Sold Qty | H1: Sold from this Lot | I1: Remaining Qty | J1: Remaining Value | L1: FIFO Engine - Auto-populated from Buy transactions
A2: =IFERROR(INDEX(SORT(FILTER(Transactions!$B:$B,(Transactions!$C:$C="Buy")*(Transactions!$B:$B<>"")),1,1),1),"") | B2: =IF(A2="","",INDEX(SORT(FILTER(Transactions!$A:$G,(Transactions!$C:$C="Buy")*(Transactions!$B:$B<>"")),2,1),1,1)) | C2: =IF(A2="","",INDEX(SORT(FILTER(Transactions!$A:$G,(Transactions!$C:$C="Buy")*(Transactions!$B:$B<>"")),2,1),1,4)) | D2: =IF(A2="","",INDEX(SORT(FILTER(Transactions!$A:$G,(Transactions!$C:$C="Buy")*(Transactions!$B:$B<>"")),2,1),1,5)) | E2: =IF(C2="","",C2*D2) | F2: =IF(A2="","",SUMIFS(C$2:C2,A$2:A2,A2,B$2:B2,"<="&B2)) | G2: =IF(A2="","",SUMIFS(Transactions!$D:$D,Transactions!$B:$B,A2,Transactions!$C:$C,"Sell")) | H2: =IF(A2="","",MAX(0,MIN(C2,G2-SUM(H$2:H1)))) | I2: =IF(C2="","",C2-H2) | J2: =IF(I2="","",I2*D2) | L2: This sheet automatically tracks which buy lots have been sold using FIFO method.
A3: =IFERROR(INDEX(SORT(FILTER(Transactions!$B:$B,(Transactions!$C:$C="Buy")*(Transactions!$B:$B<>"")),1,1),2),"") | B3: =IF(A3="","",INDEX(SORT(FILTER(Transactions!$A:$G,(Transactions!$C:$C="Buy")*(Transactions!$B:$B<>"")),2,1),2,1)) | C3: =IF(A3="","",INDEX(SORT(FILTER(Transactions!$A:$G,(Transactions!$C:$C="Buy")*(Transactions!$B:$B<>"")),2,1),2,4)) | D3: =IF(A3="","",INDEX(SORT(FILTER(Transactions!$A:$G,(Transactions!$C:$C="Buy")*(Transactions!$B:$B<>"")),2,1),2,5)) | E3: =IF(C3="","",C3*D3) | F3: =IF(A3="","",SUMIFS(C$2:C3,A$2:A3,A3,B$2:B3,"<="&B3)) | G3: =IF(A3="","",SUMIFS(Transactions!$D:$D,Transactions!$B:$B,A3,Transactions!$C:$C,"Sell")) | H3: =IF(A3="","",MAX(0,MIN(C3,G3-SUM(H$2:H2)))) | I3: =IF(C3="","",C3-H3) | J3: =IF(I3="","",I3*D3)
A4: =IFERROR(INDEX(SORT(FILTER(Transactions!$B:$B,(Transactions!$C:$C="Buy")*(Transactions!$B:$B<>"")),1,1),3),"") | B4: =IF(A4="","",INDEX(SORT(FILTER(Transactions!$A:$G,(Transactions!$C:$C="Buy")*(Transactions!$B:$B<>"")),2,1),3,1)) | C4: =IF(A4="","",INDEX(SORT(FILTER(Transactions!$A:$G,(Transactions!$C:$C="Buy")*(Transactions!$B:$B<>"")),2,1),3,4)) | D4: =IF(A4="","",INDEX(SORT(FILTER(Transactions!$A:$G,(Transactions!$C:$C="Buy")*(Transactions!$B:$B<>"")),2,1),3,5)) | E4: =IF(C4="","",C4*D4) | F4: =IF(A4="","",SUMIFS(C$2:C4,A$2:A4,A4,B$2:B4,"<="&B4)) | G4: =IF(A4="","",SUMIFS(Transactions!$D:$D,Transactions!$B:$B,A4,Transactions!$C:$C,"Sell")) | H4: =IF(A4="","",MAX(0,MIN(C4,G4-SUM(H$2:H3)))) | I4: =IF(C4="","",C4-H4) | J4: =IF(I4="","",I4*D4) | L4: How FIFO works here:
A5: =IFERROR(INDEX(SORT(FILTER(Transactions!$B:$B,(Transactions!$C:$C="Buy")*(Transactions!$B:$B<>"")),1,1),4),"") | B5: =IF(A5="","",INDEX(SORT(FILTER(Transactions!$A:$G,(Transactions!$C:$C="Buy")*(Transactions!$B:$B<>"")),2,1),4,1)) | C5: =IF(A5="","",INDEX(SORT(FILTER(Transactions!$A:$G,(Transactions!$C:$C="Buy")*(Transactions!$B:$B<>"")),2,1),4,4)) | D5: =IF(A5="","",INDEX(SORT(FILTER(Transactions!$A:$G,(Transactions!$C:$C="Buy")*(Transactions!$B:$B<>"")),2,1),4,5)) | E5: =IF(C5="","",C5*D5) | F5: =IF(A5="","",SUMIFS(C$2:C5,A$2:A5,A5,B$2:B5,"<="&B5)) | G5: =IF(A5="","",SUMIFS(Transactions!$D:$D,Transactions!$B:$B,A5,Transactions!$C:$C,"Sell")) | H5: =IF(A5="","",MAX(0,MIN(C5,G5-SUM(H$2:H4)))) | I5: =IF(C5="","",C5-H5) | J5: =IF(I5="","",I5*D5) | L5: 1. All Buy transactions are sorted by date
A6: =IFERROR(INDEX(SORT(FILTER(Transactions!$B:$B,(Transactions!$C:$C="Buy")*(Transactions!$B:$B<>"")),1,1),5),"") | B6: =IF(A6="","",INDEX(SORT(FILTER(Transactions!$A:$G,(Transactions!$C:$C="Buy")*(Transactions!$B:$B<>"")),2,1),5,1)) | C6: =IF(A6="","",INDEX(SORT(FILTER(Transactions!$A:$G,(Transactions!$C:$C="Buy")*(Transactions!$B:$B<>"")),2,1),5,4)) | D6: =IF(A6="","",INDEX(SORT(FILTER(Transactions!$A:$G,(Transactions!$C:$C="Buy")*(Transactions!$B:$B<>"")),2,1),5,5)) | E6: =IF(C6="","",C6*D6) | F6: =IF(A6="","",SUMIFS(C$2:C6,A$2:A6,A6,B$2:B6,"<="&B6)) | G6: =IF(A6="","",SUMIFS(Transactions!$D:$D,Transactions!$B:$B,A6,Transactions!$C:$C,"Sell")) | H6: =IF(A6="","",MAX(0,MIN(C6,G6-SUM(H$2:H5)))) | I6: =IF(C6="","",C6-H6) | J6: =IF(I6="","",I6*D6) | L6: 2. Sell transactions consume from oldest lots first
A7: =IFERROR(INDEX(SORT(FILTER(Transactions!$B:$B,(Transactions!$C:$C="Buy")*(Transactions!$B:$B<>"")),1,1),6),"") | B7: =IF(A7="","",INDEX(SORT(FILTER(Transactions!$A:$G,(Transactions!$C:$C="Buy")*(Transactions!$B:$B<>"")),2,1),6,1)) | C7: =IF(A7="","",INDEX(SORT(FILTER(Transactions!$A:$G,(Transactions!$C:$C="Buy")*(Transactions!$B:$B<>"")),2,1),6,4)) | D7: =IF(A7="","",INDEX(SORT(FILTER(Transactions!$A:$G,(Transactions!$C:$C="Buy")*(Transactions!$B:$B<>"")),2,1),6,5)) | E7: =IF(C7="","",C7*D7) | F7: =IF(A7="","",SUMIFS(C$2:C7,A$2:A7,A7,B$2:B7,"<="&B7)) | G7: =IF(A7="","",SUMIFS(Transactions!$D:$D,Transactions!$B:$B,A7,Transactions!$C:$C,"Sell")) | H7: =IF(A7="","",MAX(0,MIN(C7,G7-SUM(H$2:H6)))) | I7: =IF(C7="","",C7-H7) | J7: =IF(I7="","",I7*D7) | L7: 3. Remaining Qty shows unsold shares from each lot
A8: =IFERROR(INDEX(SORT(FILTER(Transactions!$B:$B,(Transactions!$C:$C="Buy")*(Transactions!$B:$B<>"")),1,1),7),"") | B8: =IF(A8="","",INDEX(SORT(FILTER(Transactions!$A:$G,(Transactions!$C:$C="Buy")*(Transactions!$B:$B<>"")),2,1),7,1)) | C8: =IF(A8="","",INDEX(SORT(FILTER(Transactions!$A:$G,(Transactions!$C:$C="Buy")*(Transactions!$B:$B<>"")),2,1),7,4)) | D8: =IF(A8="","",INDEX(SORT(FILTER(Transactions!$A:$G,(Transactions!$C:$C="Buy")*(Transactions!$B:$B<>"")),2,1),7,5)) | E8: =IF(C8="","",C8*D8) | F8: =IF(A8="","",SUMIFS(C$2:C8,A$2:A8,A8,B$2:B8,"<="&B8)) | G8: =IF(A8="","",SUMIFS(Transactions!$D:$D,Transactions!$B:$B,A8,Transactions!$C:$C,"Sell")) | H8: =IF(A8="","",MAX(0,MIN(C8,G8-SUM(H$2:H7)))) | I8: =IF(C8="","",C8-H8) | J8: =IF(I8="","",I8*D8) | L8: 4. Remaining Value = Remaining Qty × Original Buy Price
A9: =IFERROR(INDEX(SORT(FILTER(Transactions!$B:$B,(Transactions!$C:$C="Buy")*(Transactions!$B:$B<>"")),1,1),8),"") | B9: =IF(A9="","",INDEX(SORT(FILTER(Transactions!$A:$G,(Transactions!$C:$C="Buy")*(Transactions!$B:$B<>"")),2,1),8,1)) | C9: =IF(A9="","",INDEX(SORT(FILTER(Transactions!$A:$G,(Transactions!$C:$C="Buy")*(Transactions!$B:$B<>"")),2,1),8,4)) | D9: =IF(A9="","",INDEX(SORT(FILTER(Transactions!$A:$G,(Transactions!$C:$C="Buy")*(Transactions!$B:$B<>"")),2,1),8,5)) | E9: =IF(C9="","",C9*D9) | F9: =IF(A9="","",SUMIFS(C$2:C9,A$2:A9,A9,B$2:B9,"<="&B9)) | G9: =IF(A9="","",SUMIFS(Transactions!$D:$D,Transactions!$B:$B,A9,Transactions!$C:$C,"Sell")) | H9: =IF(A9="","",MAX(0,MIN(C9,G9-SUM(H$2:H8)))) | I9: =IF(C9="","",C9-H9) | J9: =IF(I9="","",I9*D9)
A10: =IFERROR(INDEX(SORT(FILTER(Transactions!$B:$B,(Transactions!$C:$C="Buy")*(Transactions!$B:$B<>"")),1,1),9),"") | B10: =IF(A10="","",INDEX(SORT(FILTER(Transactions!$A:$G,(Transactions!$C:$C="Buy")*(Transactions!$B:$B<>"")),2,1),9,1)) | C10: =IF(A10="","",INDEX(SORT(FILTER(Transactions!$A:$G,(Transactions!$C:$C="Buy")*(Transactions!$B:$B<>"")),2,1),9,4)) | D10: =IF(A10="","",INDEX(SORT(FILTER(Transactions!$A:$G,(Transactions!$C:$C="Buy")*(Transactions!$B:$B<>"")),2,1),9,5)) | E10: =IF(C10="","",C10*D10) | F10: =IF(A10="","",SUMIFS(C$2:C10,A$2:A10,A10,B$2:B10,"<="&B10)) | G10: =IF(A10="","",SUMIFS(Transactions!$D:$D,Transactions!$B:$B,A10,Transactions!$C:$C,"Sell")) | H10: =IF(A10="","",MAX(0,MIN(C10,G10-SUM(H$2:H9)))) | I10: =IF(C10="","",C10-H10) | J10: =IF(I10="","",I10*D10)
A11: =IFERROR(INDEX(SORT(FILTER(Transactions!$B:$B,(Transactions!$C:$C="Buy")*(Transactions!$B:$B<>"")),1,1),10),"") | B11: =IF(A11="","",INDEX(SORT(FILTER(Transactions!$A:$G,(Transactions!$C:$C="Buy")*(Transactions!$B:$B<>"")),2,1),10,1)) | C11: =IF(A11="","",INDEX(SORT(FILTER(Transactions!$A:$G,(Transactions!$C:$C="Buy")*(Transactions!$B:$B<>"")),2,1),10,4)) | D11: =IF(A11="","",INDEX(SORT(FILTER(Transactions!$A:$G,(Transactions!$C:$C="Buy")*(Transactions!$B:$B<>"")),2,1),10,5)) | E11: =IF(C11="","",C11*D11) | F11: =IF(A11="","",SUMIFS(C$2:C11,A$2:A11,A11,B$2:B11,"<="&B11)) | G11: =IF(A11="","",SUMIFS(Transactions!$D:$D,Transactions!$B:$B,A11,Transactions!$C:$C,"Sell")) | H11: =IF(A11="","",MAX(0,MIN(C11,G11-SUM(H$2:H10)))) | I11: =IF(C11="","",C11-H11) | J11: =IF(I11="","",I11*D11)
A12: =IFERROR(INDEX(SORT(FILTER(Transactions!$B:$B,(Transactions!$C:$C="Buy")*(Transactions!$B:$B<>"")),1,1),11),"") | B12: =IF(A12="","",INDEX(SORT(FILTER(Transactions!$A:$G,(Transactions!$C:$C="Buy")*(Transactions!$B:$B<>"")),2,1),11,1)) | C12: =IF(A12="","",INDEX(SORT(FILTER(Transactions!$A:$G,(Transactions!$C:$C="Buy")*(Transactions!$B:$B<>"")),2,1),11,4)) | D12: =IF(A12="","",INDEX(SORT(FILTER(Transactions!$A:$G,(Transactions!$C:$C="Buy")*(Transactions!$B:$B<>"")),2,1),11,5)) | E12: =IF(C12="","",C12*D12) | F12: =IF(A12="","",SUMIFS(C$2:C12,A$2:A12,A12,B$2:B12,"<="&B12)) | G12: =IF(A12="","",SUMIFS(Transactions!$D:$D,Transactions!$B:$B,A12,Transactions!$C:$C,"Sell")) | H12: =IF(A12="","",MAX(0,MIN(C12,G12-SUM(H$2:H11)))) | I12: =IF(C12="","",C12-H12) | J12: =IF(I12="","",I12*D12)
A13: =IFERROR(INDEX(SORT(FILTER(Transactions!$B:$B,(Transactions!$C:$C="Buy")*(Transactions!$B:$B<>"")),1,1),12),"") | B13: =IF(A13="","",INDEX(SORT(FILTER(Transactions!$A:$G,(Transactions!$C:$C="Buy")*(Transactions!$B:$B<>"")),2,1),12,1)) | C13: =IF(A13="","",INDEX(SORT(FILTER(Transactions!$A:$G,(Transactions!$C:$C="Buy")*(Transactions!$B:$B<>"")),2,1),12,4)) | D13: =IF(A13="","",INDEX(SORT(FILTER(Transactions!$A:$G,(Transactions!$C:$C="Buy")*(Transactions!$B:$B<>"")),2,1),12,5)) | E13: =IF(C13="","",C13*D13) | F13: =IF(A13="","",SUMIFS(C$2:C13,A$2:A13,A13,B$2:B13,"<="&B13)) | G13: =IF(A13="","",SUMIFS(Transactions!$D:$D,Transactions!$B:$B,A13,Transactions!$C:$C,"Sell")) | H13: =IF(A13="","",MAX(0,MIN(C13,G13-SUM(H$2:H12)))) | I13: =IF(C13="","",C13-H13) | J13: =IF(I13="","",I13*D13)
A14: =IFERROR(INDEX(SORT(FILTER(Transactions!$B:$B,(Transactions!$C:$C="Buy")*(Transactions!$B:$B<>"")),1,1),13),"") | B14: =IF(A14="","",INDEX(SORT(FILTER(Transactions!$A:$G,(Transactions!$C:$C="Buy")*(Transactions!$B:$B<>"")),2,1),13,1)) | C14: =IF(A14="","",INDEX(SORT(FILTER(Transactions!$A:$G,(Transactions!$C:$C="Buy")*(Transactions!$B:$B<>"")),2,1),13,4)) | D14: =IF(A14="","",INDEX(SORT(FILTER(Transactions!$A:$G,(Transactions!$C:$C="Buy")*(Transactions!$B:$B<>"")),2,1),13,5)) | E14: =IF(C14="","",C14*D14) | F14: =IF(A14="","",SUMIFS(C$2:C14,A$2:A14,A14,B$2:B14,"<="&B14)) | G14: =IF(A14="","",SUMIFS(Transactions!$D:$D,Transactions!$B:$B,A14,Transactions!$C:$C,"Sell")) | H14: =IF(A14="","",MAX(0,MIN(C14,G14-SUM(H$2:H13)))) | I14: =IF(C14="","",C14-H14) | J14: =IF(I14="","",I14*D14)
A15: =IFERROR(INDEX(SORT(FILTER(Transactions!$B:$B,(Transactions!$C:$C="Buy")*(Transactions!$B:$B<>"")),1,1),14),"") | B15: =IF(A15="","",INDEX(SORT(FILTER(Transactions!$A:$G,(Transactions!$C:$C="Buy")*(Transactions!$B:$B<>"")),2,1),14,1)) | C15: =IF(A15="","",INDEX(SORT(FILTER(Transactions!$A:$G,(Transactions!$C:$C="Buy")*(Transactions!$B:$B<>"")),2,1),14,4)) | D15: =IF(A15="","",INDEX(SORT(FILTER(Transactions!$A:$G,(Transactions!$C:$C="Buy")*(Transactions!$B:$B<>"")),2,1),14,5)) | E15: =IF(C15="","",C15*D15) | F15: =IF(A15="","",SUMIFS(C$2:C15,A$2:A15,A15,B$2:B15,"<="&B15)) | G15: =IF(A15="","",SUMIFS(Transactions!$D:$D,Transactions!$B:$B,A15,Transactions!$C:$C,"Sell")) | H15: =IF(A15="","",MAX(0,MIN(C15,G15-SUM(H$2:H14)))) | I15: =IF(C15="","",C15-H15) | J15: =IF(I15="","",I15*D15)
A16: =IFERROR(INDEX(SORT(FILTER(Transactions!$B:$B,(Transactions!$C:$C="Buy")*(Transactions!$B:$B<>"")),1,1),15),"") | B16: =IF(A16="","",INDEX(SORT(FILTER(Transactions!$A:$G,(Transactions!$C:$C="Buy")*(Transactions!$B:$B<>"")),2,1),15,1)) | C16: =IF(A16="","",INDEX(SORT(FILTER(Transactions!$A:$G,(Transactions!$C:$C="Buy")*(Transactions!$B:$B<>"")),2,1),15,4)) | D16: =IF(A16="","",INDEX(SORT(FILTER(Transactions!$A:$G,(Transactions!$C:$C="Buy")*(Transactions!$B:$B<>"")),2,1),15,5)) | E16: =IF(C16="","",C16*D16) | F16: =IF(A16="","",SUMIFS(C$2:C16,A$2:A16,A16,B$2:B16,"<="&B16)) | G16: =IF(A16="","",SUMIFS(Transactions!$D:$D,Transactions!$B:$B,A16,Transactions!$C:$C,"Sell")) | H16: =IF(A16="","",MAX(0,MIN(C16,G16-SUM(H$2:H15)))) | I16: =IF(C16="","",C16-H16) | J16: =IF(I16="","",I16*D16)
A17: =IFERROR(INDEX(SORT(FILTER(Transactions!$B:$B,(Transactions!$C:$C="Buy")*(Transactions!$B:$B<>"")),1,1),16),"") | B17: =IF(A17="","",INDEX(SORT(FILTER(Transactions!$A:$G,(Transactions!$C:$C="Buy")*(Transactions!$B:$B<>"")),2,1),16,1)) | C17: =IF(A17="","",INDEX(SORT(FILTER(Transactions!$A:$G,(Transactions!$C:$C="Buy")*(Transactions!$B:$B<>"")),2,1),16,4)) | D17: =IF(A17="","",INDEX(SORT(FILTER(Transactions!$A:$G,(Transactions!$C:$C="Buy")*(Transactions!$B:$B<>"")),2,1),16,5)) | E17: =IF(C17="","",C17*D17) | F17: =IF(A17="","",SUMIFS(C$2:C17,A$2:A17,A17,B$2:B17,"<="&B17)) | G17: =IF(A17="","",SUMIFS(Transactions!$D:$D,Transactions!$B:$B,A17,Transactions!$C:$C,"Sell")) | H17: =IF(A17="","",MAX(0,MIN(C17,G17-SUM(H$2:H16)))) | I17: =IF(C17="","",C17-H17) | J17: =IF(I17="","",I17*D17)
A18: =IFERROR(INDEX(SORT(FILTER(Transactions!$B:$B,(Transactions!$C:$C="Buy")*(Transactions!$B:$B<>"")),1,1),17),"") | B18: =IF(A18="","",INDEX(SORT(FILTER(Transactions!$A:$G,(Transactions!$C:$C="Buy")*(Transactions!$B:$B<>"")),2,1),17,1)) | C18: =IF(A18="","",INDEX(SORT(FILTER(Transactions!$A:$G,(Transactions!$C:$C="Buy")*(Transactions!$B:$B<>"")),2,1),17,4)) | D18: =IF(A18="","",INDEX(SORT(FILTER(Transactions!$A:$G,(Transactions!$C:$C="Buy")*(Transactions!$B:$B<>"")),2,1),17,5)) | E18: =IF(C18="","",C18*D18) | F18: =IF(A18="","",SUMIFS(C$2:C18,A$2:A18,A18,B$2:B18,"<="&B18)) | G18: =IF(A18="","",SUMIFS(Transactions!$D:$D,Transactions!$B:$B,A18,Transactions!$C:$C,"Sell")) | H18: =IF(A18="","",MAX(0,MIN(C18,G18-SUM(H$2:H17)))) | I18: =IF(C18="","",C18-H18) | J18: =IF(I18="","",I18*D18)
A19: =IFERROR(INDEX(SORT(FILTER(Transactions!$B:$B,(Transactions!$C:$C="Buy")*(Transactions!$B:$B<>"")),1,1),18),"") | B19: =IF(A19="","",INDEX(SORT(FILTER(Transactions!$A:$G,(Transactions!$C:$C="Buy")*(Transactions!$B:$B<>"")),2,1),18,1)) | C19: =IF(A19="","",INDEX(SORT(FILTER(Transactions!$A:$G,(Transactions!$C:$C="Buy")*(Transactions!$B:$B<>"")),2,1),18,4)) | D19: =IF(A19="","",INDEX(SORT(FILTER(Transactions!$A:$G,(Transactions!$C:$C="Buy")*(Transactions!$B:$B<>"")),2,1),18,5)) | E19: =IF(C19="","",C19*D19) | F19: =IF(A19="","",SUMIFS(C$2:C19,A$2:A19,A19,B$2:B19,"<="&B19)) | G19: =IF(A19="","",SUMIFS(Transactions!$D:$D,Transactions!$B:$B,A19,Transactions!$C:$C,"Sell")) | H19: =IF(A19="","",MAX(0,MIN(C19,G19-SUM(H$2:H18)))) | I19: =IF(C19="","",C19-H19) | J19: =IF(I19="","",I19*D19)
A20: =IFERROR(INDEX(SORT(FILTER(Transactions!$B:$B,(Transactions!$C:$C="Buy")*(Transactions!$B:$B<>"")),1,1),19),"") | B20: =IF(A20="","",INDEX(SORT(FILTER(Transactions!$A:$G,(Transactions!$C:$C="Buy")*(Transactions!$B:$B<>"")),2,1),19,1)) | C20: =IF(A20="","",INDEX(SORT(FILTER(Transactions!$A:$G,(Transactions!$C:$C="Buy")*(Transactions!$B:$B<>"")),2,1),19,4)) | D20: =IF(A20="","",INDEX(SORT(FILTER(Transactions!$A:$G,(Transactions!$C:$C="Buy")*(Transactions!$B:$B<>"")),2,1),19,5)) | E20: =IF(C20="","",C20*D20) | F20: =IF(A20="","",SUMIFS(C$2:C20,A$2:A20,A20,B$2:B20,"<="&B20)) | G20: =IF(A20="","",SUMIFS(Transactions!$D:$D,Transactions!$B:$B,A20,Transactions!$C:$C,"Sell")) | H20: =IF(A20="","",MAX(0,MIN(C20,G20-SUM(H$2:H19)))) | I20: =IF(C20="","",C20-H20) | J20: =IF(I20="","",I20*D20)
A21: =IFERROR(INDEX(SORT(FILTER(Transactions!$B:$B,(Transactions!$C:$C="Buy")*(Transactions!$B:$B<>"")),1,1),20),"") | B21: =IF(A21="","",INDEX(SORT(FILTER(Transactions!$A:$G,(Transactions!$C:$C="Buy")*(Transactions!$B:$B<>"")),2,1),20,1)) | C21: =IF(A21="","",INDEX(SORT(FILTER(Transactions!$A:$G,(Transactions!$C:$C="Buy")*(Transactions!$B:$B<>"")),2,1),20,4)) | D21: =IF(A21="","",INDEX(SORT(FILTER(Transactions!$A:$G,(Transactions!$C:$C="Buy")*(Transactions!$B:$B<>"")),2,1),20,5)) | E21: =IF(C21="","",C21*D21) | F21: =IF(A21="","",SUMIFS(C$2:C21,A$2:A21,A21,B$2:B21,"<="&B21)) | G21: =IF(A21="","",SUMIFS(Transactions!$D:$D,Transactions!$B:$B,A21,Transactions!$C:$C,"Sell")) | H21: =IF(A21="","",MAX(0,MIN(C21,G21-SUM(H$2:H20)))) | I21: =IF(C21="","",C21-H21) | J21: =IF(I21="","",I21*D21)
A22: =IFERROR(INDEX(SORT(FILTER(Transactions!$B:$B,(Transactions!$C:$C="Buy")*(Transactions!$B:$B<>"")),1,1),21),"") | B22: =IF(A22="","",INDEX(SORT(FILTER(Transactions!$A:$G,(Transactions!$C:$C="Buy")*(Transactions!$B:$B<>"")),2,1),21,1)) | C22: =IF(A22="","",INDEX(SORT(FILTER(Transactions!$A:$G,(Transactions!$C:$C="Buy")*(Transactions!$B:$B<>"")),2,1),21,4)) | D22: =IF(A22="","",INDEX(SORT(FILTER(Transactions!$A:$G,(Transactions!$C:$C="Buy")*(Transactions!$B:$B<>"")),2,1),21,5)) | E22: =IF(C22="","",C22*D22) | F22: =IF(A22="","",SUMIFS(C$2:C22,A$2:A22,A22,B$2:B22,"<="&B22)) | G22: =IF(A22="","",SUMIFS(Transactions!$D:$D,Transactions!$B:$B,A22,Transactions!$C:$C,"Sell")) | H22: =IF(A22="","",MAX(0,MIN(C22,G22-SUM(H$2:H21)))) | I22: =IF(C22="","",C22-H22) | J22: =IF(I22="","",I22*D22)
A23: =IFERROR(INDEX(SORT(FILTER(Transactions!$B:$B,(Transactions!$C:$C="Buy")*(Transactions!$B:$B<>"")),1,1),22),"") | B23: =IF(A23="","",INDEX(SORT(FILTER(Transactions!$A:$G,(Transactions!$C:$C="Buy")*(Transactions!$B:$B<>"")),2,1),22,1)) | C23: =IF(A23="","",INDEX(SORT(FILTER(Transactions!$A:$G,(Transactions!$C:$C="Buy")*(Transactions!$B:$B<>"")),2,1),22,4)) | D23: =IF(A23="","",INDEX(SORT(FILTER(Transactions!$A:$G,(Transactions!$C:$C="Buy")*(Transactions!$B:$B<>"")),2,1),22,5)) | E23: =IF(C23="","",C23*D23) | F23: =IF(A23="","",SUMIFS(C$2:C23,A$2:A23,A23,B$2:B23,"<="&B23)) | G23: =IF(A23="","",SUMIFS(Transactions!$D:$D,Transactions!$B:$B,A23,Transactions!$C:$C,"Sell")) | H23: =IF(A23="","",MAX(0,MIN(C23,G23-SUM(H$2:H22)))) | I23: =IF(C23="","",C23-H23) | J23: =IF(I23="","",I23*D23)
A24: =IFERROR(INDEX(SORT(FILTER(Transactions!$B:$B,(Transactions!$C:$C="Buy")*(Transactions!$B:$B<>"")),1,1),23),"") | B24: =IF(A24="","",INDEX(SORT(FILTER(Transactions!$A:$G,(Transactions!$C:$C="Buy")*(Transactions!$B:$B<>"")),2,1),23,1)) | C24: =IF(A24="","",INDEX(SORT(FILTER(Transactions!$A:$G,(Transactions!$C:$C="Buy")*(Transactions!$B:$B<>"")),2,1),23,4)) | D24: =IF(A24="","",INDEX(SORT(FILTER(Transactions!$A:$G,(Transactions!$C:$C="Buy")*(Transactions!$B:$B<>"")),2,1),23,5)) | E24: =IF(C24="","",C24*D24) | F24: =IF(A24="","",SUMIFS(C$2:C24,A$2:A24,A24,B$2:B24,"<="&B24)) | G24: =IF(A24="","",SUMIFS(Transactions!$D:$D,Transactions!$B:$B,A24,Transactions!$C:$C,"Sell")) | H24: =IF(A24="","",MAX(0,MIN(C24,G24-SUM(H$2:H23)))) | I24: =IF(C24="","",C24-H24) | J24: =IF(I24="","",I24*D24)
A25: =IFERROR(INDEX(SORT(FILTER(Transactions!$B:$B,(Transactions!$C:$C="Buy")*(Transactions!$B:$B<>"")),1,1),24),"") | B25: =IF(A25="","",INDEX(SORT(FILTER(Transactions!$A:$G,(Transactions!$C:$C="Buy")*(Transactions!$B:$B<>"")),2,1),24,1)) | C25: =IF(A25="","",INDEX(SORT(FILTER(Transactions!$A:$G,(Transactions!$C:$C="Buy")*(Transactions!$B:$B<>"")),2,1),24,4)) | D25: =IF(A25="","",INDEX(SORT(FILTER(Transactions!$A:$G,(Transactions!$C:$C="Buy")*(Transactions!$B:$B<>"")),2,1),24,5)) | E25: =IF(C25="","",C25*D25) | F25: =IF(A25="","",SUMIFS(C$2:C25,A$2:A25,A25,B$2:B25,"<="&B25)) | G25: =IF(A25="","",SUMIFS(Transactions!$D:$D,Transactions!$B:$B,A25,Transactions!$C:$C,"Sell")) | H25: =IF(A25="","",MAX(0,MIN(C25,G25-SUM(H$2:H24)))) | I25: =IF(C25="","",C25-H25) | J25: =IF(I25="","",I25*D25)
A26: =IFERROR(INDEX(SORT(FILTER(Transactions!$B:$B,(Transactions!$C:$C="Buy")*(Transactions!$B:$B<>"")),1,1),25),"") | B26: =IF(A26="","",INDEX(SORT(FILTER(Transactions!$A:$G,(Transactions!$C:$C="Buy")*(Transactions!$B:$B<>"")),2,1),25,1)) | C26: =IF(A26="","",INDEX(SORT(FILTER(Transactions!$A:$G,(Transactions!$C:$C="Buy")*(Transactions!$B:$B<>"")),2,1),25,4)) | D26: =IF(A26="","",INDEX(SORT(FILTER(Transactions!$A:$G,(Transactions!$C:$C="Buy")*(Transactions!$B:$B<>"")),2,1),25,5)) | E26: =IF(C26="","",C26*D26) | F26: =IF(A26="","",SUMIFS(C$2:C26,A$2:A26,A26,B$2:B26,"<="&B26)) | G26: =IF(A26="","",SUMIFS(Transactions!$D:$D,Transactions!$B:$B,A26,Transactions!$C:$C,"Sell")) | H26: =IF(A26="","",MAX(0,MIN(C26,G26-SUM(H$2:H25)))) | I26: =IF(C26="","",C26-H26) | J26: =IF(I26="","",I26*D26)
A27: =IFERROR(INDEX(SORT(FILTER(Transactions!$B:$B,(Transactions!$C:$C="Buy")*(Transactions!$B:$B<>"")),1,1),26),"") | B27: =IF(A27="","",INDEX(SORT(FILTER(Transactions!$A:$G,(Transactions!$C:$C="Buy")*(Transactions!$B:$B<>"")),2,1),26,1)) | C27: =IF(A27="","",INDEX(SORT(FILTER(Transactions!$A:$G,(Transactions!$C:$C="Buy")*(Transactions!$B:$B<>"")),2,1),26,4)) | D27: =IF(A27="","",INDEX(SORT(FILTER(Transactions!$A:$G,(Transactions!$C:$C="Buy")*(Transactions!$B:$B<>"")),2,1),26,5)) | E27: =IF(C27="","",C27*D27) | F27: =IF(A27="","",SUMIFS(C$2:C27,A$2:A27,A27,B$2:B27,"<="&B27)) | G27: =IF(A27="","",SUMIFS(Transactions!$D:$D,Transactions!$B:$B,A27,Transactions!$C:$C,"Sell")) | H27: =IF(A27="","",MAX(0,MIN(C27,G27-SUM(H$2:H26)))) | I27: =IF(C27="","",C27-H27) | J27: =IF(I27="","",I27*D27)
A28: =IFERROR(INDEX(SORT(FILTER(Transactions!$B:$B,(Transactions!$C:$C="Buy")*(Transactions!$B:$B<>"")),1,1),27),"") | B28: =IF(A28="","",INDEX(SORT(FILTER(Transactions!$A:$G,(Transactions!$C:$C="Buy")*(Transactions!$B:$B<>"")),2,1),27,1)) | C28: =IF(A28="","",INDEX(SORT(FILTER(Transactions!$A:$G,(Transactions!$C:$C="Buy")*(Transactions!$B:$B<>"")),2,1),27,4)) | D28: =IF(A28="","",INDEX(SORT(FILTER(Transactions!$A:$G,(Transactions!$C:$C="Buy")*(Transactions!$B:$B<>"")),2,1),27,5)) | E28: =IF(C28="","",C28*D28) | F28: =IF(A28="","",SUMIFS(C$2:C28,A$2:A28,A28,B$2:B28,"<="&B28)) | G28: =IF(A28="","",SUMIFS(Transactions!$D:$D,Transactions!$B:$B,A28,Transactions!$C:$C,"Sell")) | H28: =IF(A28="","",MAX(0,MIN(C28,G28-SUM(H$2:H27)))) | I28: =IF(C28="","",C28-H28) | J28: =IF(I28="","",I28*D28)
A29: =IFERROR(INDEX(SORT(FILTER(Transactions!$B:$B,(Transactions!$C:$C="Buy")*(Transactions!$B:$B<>"")),1,1),28),"") | B29: =IF(A29="","",INDEX(SORT(FILTER(Transactions!$A:$G,(Transactions!$C:$C="Buy")*(Transactions!$B:$B<>"")),2,1),28,1)) | C29: =IF(A29="","",INDEX(SORT(FILTER(Transactions!$A:$G,(Transactions!$C:$C="Buy")*(Transactions!$B:$B<>"")),2,1),28,4)) | D29: =IF(A29="","",INDEX(SORT(FILTER(Transactions!$A:$G,(Transactions!$C:$C="Buy")*(Transactions!$B:$B<>"")),2,1),28,5)) | E29: =IF(C29="","",C29*D29) | F29: =IF(A29="","",SUMIFS(C$2:C29,A$2:A29,A29,B$2:B29,"<="&B29)) | G29: =IF(A29="","",SUMIFS(Transactions!$D:$D,Transactions!$B:$B,A29,Transactions!$C:$C,"Sell")) | H29: =IF(A29="","",MAX(0,MIN(C29,G29-SUM(H$2:H28)))) | I29: =IF(C29="","",C29-H29) | J29: =IF(I29="","",I29*D29)
A30: =IFERROR(INDEX(SORT(FILTER(Transactions!$B:$B,(Transactions!$C:$C="Buy")*(Transactions!$B:$B<>"")),1,1),29),"") | B30: =IF(A30="","",INDEX(SORT(FILTER(Transactions!$A:$G,(Transactions!$C:$C="Buy")*(Transactions!$B:$B<>"")),2,1),29,1)) | C30: =IF(A30="","",INDEX(SORT(FILTER(Transactions!$A:$G,(Transactions!$C:$C="Buy")*(Transactions!$B:$B<>"")),2,1),29,4)) | D30: =IF(A30="","",INDEX(SORT(FILTER(Transactions!$A:$G,(Transactions!$C:$C="Buy")*(Transactions!$B:$B<>"")),2,1),29,5)) | E30: =IF(C30="","",C30*D30) | F30: =IF(A30="","",SUMIFS(C$2:C30,A$2:A30,A30,B$2:B30,"<="&B30)) | G30: =IF(A30="","",SUMIFS(Transactions!$D:$D,Transactions!$B:$B,A30,Transactions!$C:$C,"Sell")) | H30: =IF(A30="","",MAX(0,MIN(C30,G30-SUM(H$2:H29)))) | I30: =IF(C30="","",C30-H30) | J30: =IF(I30="","",I30*D30)
A31: =IFERROR(INDEX(SORT(FILTER(Transactions!$B:$B,(Transactions!$C:$C="Buy")*(Transactions!$B:$B<>"")),1,1),30),"") | B31: =IF(A31="","",INDEX(SORT(FILTER(Transactions!$A:$G,(Transactions!$C:$C="Buy")*(Transactions!$B:$B<>"")),2,1),30,1)) | C31: =IF(A31="","",INDEX(SORT(FILTER(Transactions!$A:$G,(Transactions!$C:$C="Buy")*(Transactions!$B:$B<>"")),2,1),30,4)) | D31: =IF(A31="","",INDEX(SORT(FILTER(Transactions!$A:$G,(Transactions!$C:$C="Buy")*(Transactions!$B:$B<>"")),2,1),30,5)) | E31: =IF(C31="","",C31*D31) | F31: =IF(A31="","",SUMIFS(C$2:C31,A$2:A31,A31,B$2:B31,"<="&B31)) | G31: =IF(A31="","",SUMIFS(Transactions!$D:$D,Transactions!$B:$B,A31,Transactions!$C:$C,"Sell")) | H31: =IF(A31="","",MAX(0,MIN(C31,G31-SUM(H$2:H30)))) | I31: =IF(C31="","",C31-H31) | J31: =IF(I31="","",I31*D31)
A32: =IFERROR(INDEX(SORT(FILTER(Transactions!$B:$B,(Transactions!$C:$C="Buy")*(Transactions!$B:$B<>"")),1,1),31),"") | B32: =IF(A32="","",INDEX(SORT(FILTER(Transactions!$A:$G,(Transactions!$C:$C="Buy")*(Transactions!$B:$B<>"")),2,1),31,1)) | C32: =IF(A32="","",INDEX(SORT(FILTER(Transactions!$A:$G,(Transactions!$C:$C="Buy")*(Transactions!$B:$B<>"")),2,1),31,4)) | D32: =IF(A32="","",INDEX(SORT(FILTER(Transactions!$A:$G,(Transactions!$C:$C="Buy")*(Transactions!$B:$B<>"")),2,1),31,5)) | E32: =IF(C32="","",C32*D32) | F32: =IF(A32="","",SUMIFS(C$2:C32,A$2:A32,A32,B$2:B32,"<="&B32)) | G32: =IF(A32="","",SUMIFS(Transactions!$D:$D,Transactions!$B:$B,A32,Transactions!$C:$C,"Sell")) | H32: =IF(A32="","",MAX(0,MIN(C32,G32-SUM(H$2:H31)))) | I32: =IF(C32="","",C32-H32) | J32: =IF(I32="","",I32*D32)
A33: =IFERROR(INDEX(SORT(FILTER(Transactions!$B:$B,(Transactions!$C:$C="Buy")*(Transactions!$B:$B<>"")),1,1),32),"") | B33: =IF(A33="","",INDEX(SORT(FILTER(Transactions!$A:$G,(Transactions!$C:$C="Buy")*(Transactions!$B:$B<>"")),2,1),32,1)) | C33: =IF(A33="","",INDEX(SORT(FILTER(Transactions!$A:$G,(Transactions!$C:$C="Buy")*(Transactions!$B:$B<>"")),2,1),32,4)) | D33: =IF(A33="","",INDEX(SORT(FILTER(Transactions!$A:$G,(Transactions!$C:$C="Buy")*(Transactions!$B:$B<>"")),2,1),32,5)) | E33: =IF(C33="","",C33*D33) | F33: =IF(A33="","",SUMIFS(C$2:C33,A$2:A33,A33,B$2:B33,"<="&B33)) | G33: =IF(A33="","",SUMIFS(Transactions!$D:$D,Transactions!$B:$B,A33,Transactions!$C:$C,"Sell")) | H33: =IF(A33="","",MAX(0,MIN(C33,G33-SUM(H$2:H32)))) | I33: =IF(C33="","",C33-H33) | J33: =IF(I33="","",I33*D33)
A34: =IFERROR(INDEX(SORT(FILTER(Transactions!$B:$B,(Transactions!$C:$C="Buy")*(Transactions!$B:$B<>"")),1,1),33),"") | B34: =IF(A34="","",INDEX(SORT(FILTER(Transactions!$A:$G,(Transactions!$C:$C="Buy")*(Transactions!$B:$B<>"")),2,1),33,1)) | C34: =IF(A34="","",INDEX(SORT(FILTER(Transactions!$A:$G,(Transactions!$C:$C="Buy")*(Transactions!$B:$B<>"")),2,1),33,4)) | D34: =IF(A34="","",INDEX(SORT(FILTER(Transactions!$A:$G,(Transactions!$C:$C="Buy")*(Transactions!$B:$B<>"")),2,1),33,5)) | E34: =IF(C34="","",C34*D34) | F34: =IF(A34="","",SUMIFS(C$2:C34,A$2:A34,A34,B$2:B34,"<="&B34)) | G34: =IF(A34="","",SUMIFS(Transactions!$D:$D,Transactions!$B:$B,A34,Transactions!$C:$C,"Sell")) | H34: =IF(A34="","",MAX(0,MIN(C34,G34-SUM(H$2:H33)))) | I34: =IF(C34="","",C34-H34) | J34: =IF(I34="","",I34*D34)
A35: =IFERROR(INDEX(SORT(FILTER(Transactions!$B:$B,(Transactions!$C:$C="Buy")*(Transactions!$B:$B<>"")),1,1),34),"") | B35: =IF(A35="","",INDEX(SORT(FILTER(Transactions!$A:$G,(Transactions!$C:$C="Buy")*(Transactions!$B:$B<>"")),2,1),34,1)) | C35: =IF(A35="","",INDEX(SORT(FILTER(Transactions!$A:$G,(Transactions!$C:$C="Buy")*(Transactions!$B:$B<>"")),2,1),34,4)) | D35: =IF(A35="","",INDEX(SORT(FILTER(Transactions!$A:$G,(Transactions!$C:$C="Buy")*(Transactions!$B:$B<>"")),2,1),34,5)) | E35: =IF(C35="","",C35*D35) | F35: =IF(A35="","",SUMIFS(C$2:C35,A$2:A35,A35,B$2:B35,"<="&B35)) | G35: =IF(A35="","",SUMIFS(Transactions!$D:$D,Transactions!$B:$B,A35,Transactions!$C:$C,"Sell")) | H35: =IF(A35="","",MAX(0,MIN(C35,G35-SUM(H$2:H34)))) | I35: =IF(C35="","",C35-H35) | J35: =IF(I35="","",I35*D35)
A36: =IFERROR(INDEX(SORT(FILTER(Transactions!$B:$B,(Transactions!$C:$C="Buy")*(Transactions!$B:$B<>"")),1,1),35),"") | B36: =IF(A36="","",INDEX(SORT(FILTER(Transactions!$A:$G,(Transactions!$C:$C="Buy")*(Transactions!$B:$B<>"")),2,1),35,1)) | C36: =IF(A36="","",INDEX(SORT(FILTER(Transactions!$A:$G,(Transactions!$C:$C="Buy")*(Transactions!$B:$B<>"")),2,1),35,4)) | D36: =IF(A36="","",INDEX(SORT(FILTER(Transactions!$A:$G,(Transactions!$C:$C="Buy")*(Transactions!$B:$B<>"")),2,1),35,5)) | E36: =IF(C36="","",C36*D36) | F36: =IF(A36="","",SUMIFS(C$2:C36,A$2:A36,A36,B$2:B36,"<="&B36)) | G36: =IF(A36="","",SUMIFS(Transactions!$D:$D,Transactions!$B:$B,A36,Transactions!$C:$C,"Sell")) | H36: =IF(A36="","",MAX(0,MIN(C36,G36-SUM(H$2:H35)))) | I36: =IF(C36="","",C36-H36) | J36: =IF(I36="","",I36*D36)
A37: =IFERROR(INDEX(SORT(FILTER(Transactions!$B:$B,(Transactions!$C:$C="Buy")*(Transactions!$B:$B<>"")),1,1),36),"") | B37: =IF(A37="","",INDEX(SORT(FILTER(Transactions!$A:$G,(Transactions!$C:$C="Buy")*(Transactions!$B:$B<>"")),2,1),36,1)) | C37: =IF(A37="","",INDEX(SORT(FILTER(Transactions!$A:$G,(Transactions!$C:$C="Buy")*(Transactions!$B:$B<>"")),2,1),36,4)) | D37: =IF(A37="","",INDEX(SORT(FILTER(Transactions!$A:$G,(Transactions!$C:$C="Buy")*(Transactions!$B:$B<>"")),2,1),36,5)) | E37: =IF(C37="","",C37*D37) | F37: =IF(A37="","",SUMIFS(C$2:C37,A$2:A37,A37,B$2:B37,"<="&B37)) | G37: =IF(A37="","",SUMIFS(Transactions!$D:$D,Transactions!$B:$B,A37,Transactions!$C:$C,"Sell")) | H37: =IF(A37="","",MAX(0,MIN(C37,G37-SUM(H$2:H36)))) | I37: =IF(C37="","",C37-H37) | J37: =IF(I37="","",I37*D37)
A38: =IFERROR(INDEX(SORT(FILTER(Transactions!$B:$B,(Transactions!$C:$C="Buy")*(Transactions!$B:$B<>"")),1,1),37),"") | B38: =IF(A38="","",INDEX(SORT(FILTER(Transactions!$A:$G,(Transactions!$C:$C="Buy")*(Transactions!$B:$B<>"")),2,1),37,1)) | C38: =IF(A38="","",INDEX(SORT(FILTER(Transactions!$A:$G,(Transactions!$C:$C="Buy")*(Transactions!$B:$B<>"")),2,1),37,4)) | D38: =IF(A38="","",INDEX(SORT(FILTER(Transactions!$A:$G,(Transactions!$C:$C="Buy")*(Transactions!$B:$B<>"")),2,1),37,5)) | E38: =IF(C38="","",C38*D38) | F38: =IF(A38="","",SUMIFS(C$2:C38,A$2:A38,A38,B$2:B38,"<="&B38)) | G38: =IF(A38="","",SUMIFS(Transactions!$D:$D,Transactions!$B:$B,A38,Transactions!$C:$C,"Sell")) | H38: =IF(A38="","",MAX(0,MIN(C38,G38-SUM(H$2:H37)))) | I38: =IF(C38="","",C38-H38) | J38: =IF(I38="","",I38*D38)
A39: =IFERROR(INDEX(SORT(FILTER(Transactions!$B:$B,(Transactions!$C:$C="Buy")*(Transactions!$B:$B<>"")),1,1),38),"") | B39: =IF(A39="","",INDEX(SORT(FILTER(Transactions!$A:$G,(Transactions!$C:$C="Buy")*(Transactions!$B:$B<>"")),2,1),38,1)) | C39: =IF(A39="","",INDEX(SORT(FILTER(Transactions!$A:$G,(Transactions!$C:$C="Buy")*(Transactions!$B:$B<>"")),2,1),38,4)) | D39: =IF(A39="","",INDEX(SORT(FILTER(Transactions!$A:$G,(Transactions!$C:$C="Buy")*(Transactions!$B:$B<>"")),2,1),38,5)) | E39: =IF(C39="","",C39*D39) | F39: =IF(A39="","",SUMIFS(C$2:C39,A$2:A39,A39,B$2:B39,"<="&B39)) | G39: =IF(A39="","",SUMIFS(Transactions!$D:$D,Transactions!$B:$B,A39,Transactions!$C:$C,"Sell")) | H39: =IF(A39="","",MAX(0,MIN(C39,G39-SUM(H$2:H38)))) | I39: =IF(C39="","",C39-H39) | J39: =IF(I39="","",I39*D39)
A40: =IFERROR(INDEX(SORT(FILTER(Transactions!$B:$B,(Transactions!$C:$C="Buy")*(Transactions!$B:$B<>"")),1,1),39),"") | B40: =IF(A40="","",INDEX(SORT(FILTER(Transactions!$A:$G,(Transactions!$C:$C="Buy")*(Transactions!$B:$B<>"")),2,1),39,1)) | C40: =IF(A40="","",INDEX(SORT(FILTER(Transactions!$A:$G,(Transactions!$C:$C="Buy")*(Transactions!$B:$B<>"")),2,1),39,4)) | D40: =IF(A40="","",INDEX(SORT(FILTER(Transactions!$A:$G,(Transactions!$C:$C="Buy")*(Transactions!$B:$B<>"")),2,1),39,5)) | E40: =IF(C40="","",C40*D40) | F40: =IF(A40="","",SUMIFS(C$2:C40,A$2:A40,A40,B$2:B40,"<="&B40)) | G40: =IF(A40="","",SUMIFS(Transactions!$D:$D,Transactions!$B:$B,A40,Transactions!$C:$C,"Sell")) | H40: =IF(A40="","",MAX(0,MIN(C40,G40-SUM(H$2:H39)))) | I40: =IF(C40="","",C40-H40) | J40: =IF(I40="","",I40*D40)
...

Sheet Holdings
A1: Stock Name | B1: Net Holding Qty | C1: Current Avg Price | D1: Total Invested Value | E1: CMP | F1: Current Value | G1: Unrealized P&L | I1: Note: CMP Column
A2: =IFERROR(UNIQUE(FILTER(Transactions!B:B,(Transactions!C:C="Buy")*(Transactions!B:B<>""))),"") | B2: =IF(A2="","",SUMIFS(Transactions!D:D,Transactions!B:B,A2,Transactions!C:C,"Buy")-SUMIFS(Transactions!D:D,Transactions!B:B,A2,Transactions!C:C,"Sell")) | C2: =IF(B2="","",IF(B2<=0,"",SUMIFS(Transactions!G:G,Transactions!B:B,A2,Transactions!C:C,"Buy")/SUMIFS(Transactions!D:D,Transactions!B:B,A2,Transactions!C:C,"Buy"))) | D2: =IF(B2="","",IF(B2<=0,"",B2*C2)) | F2: =IF(E2="","",B2*E2) | G2: =IF(F2="","",F2-D2) | I2: Enter current market price manually or use Excel Stock Data Type

Sheet Stock_Template
A1: Stock Name: | B1: ENTER_STOCK_NAME_HERE
A3: Realized P&L | B3: Unrealized P&L | C3: Current Holding Qty | D3: Current Invested Value | E3: Average Buy Price
A4: =IF(B1="ENTER_STOCK_NAME_HERE","",SUMIFS(Transactions!G:G,Transactions!B:B,B1,Transactions!C:C,"Sell")-SUMIFS(Transactions!D:D,Transactions!B:B,B1,Transactions!C:C,"Sell")*SUMIFS(Transactions!G:G,Transactions!B:B,B1,Transactions!C:C,"Buy")/SUMIFS(Transactions!D:D,Transactions!B:B,B1,Transactions!C:C,"Buy")) | B4: =IF(B1="ENTER_STOCK_NAME_HERE","",INDEX(Holdings!G:G,MATCH(B1,Holdings!A:A,0))) | C4: =IF(B1="ENTER_STOCK_NAME_HERE","",SUMIFS(Transactions!D:D,Transactions!B:B,B1,Transactions!C:C,"Buy")-SUMIFS(Transactions!D:D,Transactions!B:B,B1,Transactions!C:C,"Sell")) | D4: =IF(B1="ENTER_STOCK_NAME_HERE","",INDEX(Holdings!D:D,MATCH(B1,Holdings!A:A,0))) | E4: =IF(B1="ENTER_STOCK_NAME_HERE","",SUMIFS(Transactions!G:G,Transactions!B:B,B1,Transactions!C:C,"Buy")/SUMIFS(Transactions!D:D,Transactions!B:B,B1,Transactions!C:C,"Buy"))
A6: Instructions: Enter stock name in B1, then duplicate this sheet for each stock you want to track individually.
A7: COMPLETE TRANSACTION HISTORY
A8: Date | B8: Stock Name | C8: Type | D8: Quantity | E8: Price | F8: Brokerage/STT | G8: Total Amount
A9: =IFERROR(FILTER(Transactions!A:G,Transactions!B:B=B1,"No transactions found"),"")
